<?xml version="1.0" ?>
<robot name="qbot" xmlns:xacro="http://www.ros.org/wiki/xacro">
	<material name="black">
		<color rgba="0.0 0.0 0.0 1.0"/>
	</material>
	<material name="blue">
		<color rgba="0.203125 0.23828125 0.28515625 1.0"/>
	</material>
	<material name="green">
		<color rgba="0.0 0.8 0.0 1.0"/>
	</material>
	<material name="grey">
		<color rgba="0.2 0.2 0.2 1.0"/>
	</material>
	<material name="orange">
		<color rgba="1.0 0.423529411765 0.0392156862745 1.0"/>
	</material>
	<material name="brown">
		<color rgba="0.870588235294 0.811764705882 0.764705882353 1.0"/>
	</material>
	<material name="red">
		<color rgba="0.80078125 0.12890625 0.1328125 1.0"/>
	</material>
	<material name="white">
		<color rgba="1.0 1.0 1.0 1.0"/>
	</material>
	
	<gazebo reference="link_chassis">
		<material>Gazebo/Orange</material>
	</gazebo>
	<gazebo reference="link_left_wheel">
		<material>Gazebo/Black</material>
	</gazebo>
	<gazebo reference="link_right_wheel">
		<material>Gazebo/Black</material>
	</gazebo>

	<link name="base_link" />

	<joint name="base_joint" type="fixed">
		<origin rpy="0 0 0" xyz="0 0 0"/>
		<child link="link_chassis"/>
		<parent link="base_link"/>
	</joint>	
	
	<link name="link_chassis">
		<!-- pose and inertial -->
		<pose>0 0 0.1 0 0 0</pose>
		<inertial>
			<mass value="5"/>
			<origin rpy="0 0 0" xyz="0 0 0.1"/>
			<inertia ixx="0.0395416666667" ixy="0" ixz="0" iyy="0.106208333333" iyz="0" izz="0.106208333333"/>
		</inertial>
		<!-- body -->
		<collision name="collision_chassis">
			<geometry>
				<box size="0.5 0.3 0.01"/>
			</geometry>
		</collision>
		<visual>
			<origin rpy="0 0 0" xyz="0 0 0"/>
			<geometry>
				<box size="0.5 0.3 0.01"/>
			</geometry>
			<material name="black"/>
		</visual>	
	</link>
	
	<link name="link_right_wheel">
		<inertial>
			<mass value="0.2"/>
			<origin rpy="0 0 0" xyz="0 0 0"/>
			<inertia ixx="0.000526666666667" ixy="0" ixz="0" iyy="0.000526666666667" iyz="0" izz="0.001"/>
		</inertial>
		<collision name="link_right_wheel_collision">
			<origin rpy="0 0 0" xyz="0 0 0"/>
			<geometry>
				<cylinder length="0.1" radius="0.1"/>
			</geometry>
			<surface>
				<friction>
					<ode>
						<mu1>1.2</mu1>
						<mu2>1.2</mu2>
						<kp>500000.0</kp>
						<kd>10.0</kd>
						<minDepth>0.001</minDepth>
						<maxVel>0.1</maxVel>
					</ode>
				</friction>
			</surface>
		</collision>
		<visual name="link_right_wheel_visual">
			<origin rpy="0 0 0" xyz="0 0 0"/>
			<geometry>
				<cylinder length="0.1" radius="0.1"/>
			</geometry>
			<material name="black"/>
		</visual>
	</link>
	
	<joint name="joint_right_wheel" type="continuous">
		<origin rpy="0 0 0" xyz="0.25 -0.15 0.055"/>
		<child link="link_right_wheel"/>
		<parent link="link_chassis"/>
		<axis rpy="0 0 0" xyz="0 0 1"/>
		<limit effort="10000" velocity="1000"/>
		<joint_properties damping="1.0" friction="1.0"/>
	</joint>
	
	<link name="link_left_wheel">
		<inertial>
			<mass value="0.2"/>
			<origin rpy="0 0 0" xyz="0 0 0"/>
			<inertia ixx="0.000526666666667" ixy="0" ixz="0" iyy="0.000526666666667" iyz="0" izz="0.001"/>
		</inertial>
		<collision name="link_left_wheel_collision">
			<origin rpy="0 0 0" xyz="0 0 0"/>
			<geometry>
				<cylinder length="0.1" radius="0.1"/>
			</geometry>
			<surface>
				<friction>
					<ode>
						<mu1>1.2</mu1>
						<mu2>1.2</mu2>
						<kp>500000.0</kp>
						<kd>10.0</kd>
						<minDepth>0.001</minDepth>
						<maxVel>0.1</maxVel>
					</ode>
				</friction>
			</surface>
		</collision>
		<visual name="link_left_wheel_visual">
			<origin rpy="0 0 0" xyz="0 0 0"/>
			<geometry>
				<cylinder length="0.1" radius="0.1"/>
			</geometry>
			<material name="black"/>
		</visual>
	</link>
	
	<joint name="joint_left_wheel" type="continuous">
		<origin rpy="0 0 0" xyz="0.25 0.15 0.055"/>
		<child link="link_left_wheel"/>
		<parent link="link_chassis"/>
		<axis rpy="0 0 0" xyz="0 0 1"/>
		<limit effort="10000" velocity="1000"/>
		<joint_properties damping="1.0" friction="1.0"/>
	</joint>

	<gazebo>
		<plugin name="joint_states" filename="libgazebo_ros_joint_state_publisher.so">
			<joint_name>joint_right_wheel</joint_name>
			<joint_name>joint_left_wheel</joint_name>
		</plugin>
	</gazebo>
</robot>
